Workbook

Sheet 테스트 개요
B1: HomeShield 테스트 개요
B3: 1. 테스트 개요
B4: 테스트 제목 | C4: HomeShield 사용자 테스트케이스
B5: 테스트 목적 | C5: 전세사기 방지·임대차 계약 분석 서비스의 사용자 주요 기능 검증
B6: 대상 서비스 | C6: HomeShield (계약서 분석 · OCR 진단 · AI 상담)
B7: 작성일 | C7: =IF(TC_DEV!C4="","",TC_DEV!C4) -> 46234 | E7: 작성자 | F7: 김진남
B9: 2. 테스트 항목
B10: 대분류 | C10: 세부 항목 (중분류) | F10: 케이스 수
B11: 회원 | C11: 회원가입, 로그인, 로그아웃, 회원 탈퇴 | F11: 10
B12: 홈 | C12: 주요 기능 이동 | F12: 3
B13: 계약 분석 | C13: 파일 업로드, OCR 진단 | F13: 9
B14: 위험 보고서 | C14: 보고서 항목, 이전 기록 진입, 기타 | F14: 5
B15: AI 상담 | C15: 상담 기능, 대화 관리 | F15: 7
B16: 알림 | C16: 알림 UI, 알림 기능 | F16: 5
B17: 마이페이지 | C17: 회원정보 이동, 프로필 변경, 조회 기능 | F17: 7
B18: 합계 | F18: =SUM(F11:F17) -> 46
B19: ※ 케이스 수는 TC_DEV 시트 기준 스냅샷입니다.
B21: 3. 테스트 일정
B22: 시작일 | C22: 46233
B23: 종료일 | C23: 46234
B24: 테스트 기간 | C24: =IFERROR(C23-C22&"일","") -> 1일
B26: 4. 결과 보고서 (TC_DEV 자동 연동)
B27: 상태 | C27: 개수 | D27: 비율 | E27: 진행률
B28: Pass | C28: =TC_DEV!C9 -> 46 | D28: =TC_DEV!D9 -> 1 | E28: =IFERROR(REPT("█",ROUND(TC_DEV!D9*30,0)),"") -> ██████████████████████████████
B29: Fail | C29: =TC_DEV!C10 -> 0 | D29: =TC_DEV!D10 -> 0 | E29: =IFERROR(REPT("█",ROUND(TC_DEV!D10*30,0)),"")
B30: Not Test | C30: =TC_DEV!C11 -> 0 | D30: =TC_DEV!D11 -> 0 | E30: =IFERROR(REPT("█",ROUND(TC_DEV!D11*30,0)),"")
B31: N/A | C31: =TC_DEV!C12 -> 0 | D31: =TC_DEV!D12 -> 0 | E31: =IFERROR(REPT("█",ROUND(TC_DEV!D12*30,0)),"")
B32: 합계 | C32: =TC_DEV!C13 -> 46 | D32: =TC_DEV!D13 -> 1
B34: 5. 결과 코멘트
B35: 테스트 결과 전체 46건의 테스트 케이스를 수행하여 모두 Pass 처리되었습니다. 회원가입·로그인, 계약서 업로드 및 OCR 진단, 위험 보고서, AI 상담, 알림, 마이페이지 등 주요 기능 흐름이 정상 시나리오 기준으로 모두 정상 동작함을 확인하였습니다. 제한 사항 계약서 파일 오입력 및 일부 예외 처리 케이스는 이번 테스트 범위에서 제외되었습니다. 다만 해당 항목은 시연에 필요한 필수 기능에 해당하지 않으며, 정상 시나리오 기준의 핵심 기능 검증 결과에는 영향을 주지 않습니다. QA 종합 의견 기본 기능 검증 기준으로 결함이 발견되지 않았고 주요 사용자 플로우가 안정적으로 동작하므로, 현재 빌드는 시연용으로 충분하다고 판단됩니다. 다만 정식 릴리스 전에는 파일 오입력·예외 케이스에 대한 추가 검증을 권장합니다.
B37: 진행 완료율 | C37: =IFERROR((TC_DEV!C9+TC_DEV!C10)/TC_DEV!C13,0) -> 1
B38: 합격률(Pass Rate) | C38: =IFERROR(TC_DEV!C9/(TC_DEV!C9+TC_DEV!C10),0) -> 1
B39: ※ 진행 완료율 = (Pass+Fail)/전체, 합격률 = Pass/(Pass+Fail)

Sheet TC_DEV
B1: HomeShield 사용자 테스트케이스
B3: ■ 테스트 정보
B4: 작성일 | C4: 46234
B5: 작성자 | C5: 김진남
B6: 테스트 진행자 | C6: 김진남
B7: ■ 테스트 결과 요약 (H열 Pass/Fail 기준 자동 집계)
B8: 상태 | C8: 개수 | D8: 비율 | E8: 진행률
B9: Pass | C9: =COUNTIF(H17:H62,"Pass") -> 46 | D9: =IFERROR(C9/$C$13,0) -> 1 | E9: =IFERROR(REPT("█",ROUND(C9/$C$13*15,0)),"") -> ███████████████
B10: Fail | C10: =COUNTIF(H17:H62,"Fail") -> 0 | D10: =IFERROR(C10/$C$13,0) -> 0 | E10: =IFERROR(REPT("█",ROUND(C10/$C$13*15,0)),"")
B11: Not Test | C11: =COUNTIF(H17:H62,"Not Test") -> 0 | D11: =IFERROR(C11/$C$13,0) -> 0 | E11: =IFERROR(REPT("█",ROUND(C11/$C$13*15,0)),"")
B12: N/A | C12: =COUNTIF(H17:H62,"N/A") -> 0 | D12: =IFERROR(C12/$C$13,0) -> 0 | E12: =IFERROR(REPT("█",ROUND(C12/$C$13*15,0)),"")
B13: 합계 | C13: =COUNTA(H17:H62) -> 46 | D13: =IFERROR(C13/$C$13,0) -> 1
B16: 케이스넘버 | C16: 대분류 | D16: 중분류 | E16: 소분류 | F16: 재현스탭 | G16: 기대사항 | H16: Pass/Fail | I16: 비고
B17: TC-001 | C17: 회원 | D17: 회원가입 | E17: 이메일 | F17: 이메일로 시작하기 > 정보 입력 > 필수 약관 동의 >회원가입 클릭 | G17: 가입이 완료되고 로그인 또는 홈 화면으로 이동한다. | H17: Pass
B18: TC-002 | F18: 회원가입 화면에서 이용약관 및 개인정보 처리방침의 보기 클릭 | G18: 선택한 약관 내용이 모달로 표시된다. | H18: Pass
B19: TC-003 | E19: 카카오 | F19: 카카오로 시작하기 > 카카오 인증 > 닉네임·약관 입력 > 가입 완료 | G19: 카카오 계정으로 회원가입되고 서비스에 진입한다. | H19: Pass | I19: 카카오 설정 필요
B20: TC-004 | F20: 회원가입 화면에서 이용약관 및 개인정보 처리방침의 보기 클릭 | G20: 선택한 약관 내용이 모달로 표시된다. | H20: Pass
B21: TC-005 | D21: 로그인 | E21: 이메일 | F21: 이메일로 가입한 계정으로 로그인 시도 | G21: 로그인되고 홈 화면으로 이동한다. | H21: Pass
B22: TC-006 | E22: 카카오 | F22: 카카오로 가입한 계정으로 로그인 시도 | G22: 로그인되고 홈 화면으로 이동한다. | H22: Pass | I22: 카카오 설정 필요
B23: TC-007 | E23: 로그인 상태 유지 | F23: 로그인 > 페이지 새로고침 | G23: 로그인 상태가 유지된다. | H23: Pass
B24: TC-007 | F24: 로그인 > 브라우저 재접속 | G24: 로그인 상태가 유지된다. | H24: Pass
B25: TC-008 | E25: 로그아웃 | F25: 로그인 상태에서 로그아웃 클릭 | G25: 세션이 종료되고 비회원 상태로 전환된다. | H25: Pass
B26: TC-009 | C26: 홈 | D26: 주요 기능 이동 | E26: 계약서 분석 | F26: 홈에서 계약서 분석 클릭 | G26: 선택한 기능 화면으로 정상 이동한다. | H26: Pass
B27: TC-010 | E27: AI 상담 | F27: 홈에서 AI 상담 클릭 | G27: 선택한 기능 화면으로 정상 이동한다. | H27: Pass
B28: TC-011 | E28: 마이페이지 | F28: 홈에서 마이페이지 클릭 | G28: 선택한 기능 화면으로 정상 이동한다. | H28: Pass
B29: TC-012 | C29: 계약 분석 | D29: 파일 업로드 | E29: 단일 업로드 | F29: 계약 분석 → 임대차계약서·등기부등본·건축물대장을 각각 업로드 | G29: 각 영역에 업로드한 파일명과 용량이 표시된다. | H29: Pass | I29: PDF·PNG·JPG
B30: TC-013 | E30: 다중 업로드 | F30: 한 서류 영역에 여러 장의 파일을 업로드 | G30: 선택한 파일이 모두 목록에 표시된다. | H30: Pass | I30: 전체 최대 10개
B31: TC-014 | E31: 업로드 종류 확인 | F31: PNG, JPG 파일 업로드 | G31: PNG, JPG 파일 업로드 파일명 및 용량이 표시된다 | H31: Pass
B32: TC-015 | F32: PDF 파일 업로드 | G32: PDF 파일 업로드 파일명 및 용량이 표시된다 | H32: Pass
B33: TC-016 | E33: 파일 제거 | F33: 업로드된 파일의 제거 버튼 클릭 | G33: 선택한 파일이 업로드 목록에서 제거된다. | H33: Pass | I33: 분석 시작 전
B34: TC-017 | D34: OCR 진단 | E34: OCR 진단 시작 | F34: 서류 3종 업로드 → OCR 진단하기 클릭 | G34: 분석 시작 안내가 표시되고 분석 상태가 진행 중으로 변경된다. | H34: Pass | I34: 약 30초~2분
B35: TC-018 | E35: OCR 진행 중 | F35: 타 페이지 이동 시, OCR 진단 진행사항 확인 | G35: OCR 중단 알림이 오지 않고 페이지 이동이 가능하다 | H35: Pass
B36: TC-019 | F36: ㄴ OCR 진단 시작 알람 터치 | G36: OCR 진행 안내 페이지로 이동한다. | H36: Pass
B37: TC-020 | E37: 백그라운드 분석 | F37: 분석 시작 → 안내창 닫기 또는 AI 상담 화면으로 이동 | G37: 화면을 이동해도 분석이 계속 진행된다. | H37: Pass
B38: TC-021 | C38: 위험 보고서 | D38: 보고서 항목 | E38: 분석 결과 확인 | F38: 분석 완료 → 결과 보기 또는 완료 알림 클릭 | G38: 해당 계약의 종합 리스크 보고서가 표시된다. | H38: Pass
B39: TC-022 | E39: 보고서 상세 확인 | F39: 위험 보고서의 각 영역 확인 | G39: 안전 점수, 계약 조건, 위험 항목, 특약 분석, 권장 조치, 위치 정보가 표시된다. | H39: Pass | I39: 결과에 따라 내용 상이
B40: TC-023 | E40: PDF 다운로드 | F40: 위험 보고서 → PDF 다운로드 클릭 | G40: 브라우저 인쇄/PDF 저장 화면이 열린다. | H40: Pass
B41: TC-024 | D41: 이전 기록 진입 | E41: 분석 내역 조회 | F41: 상단 메뉴에서 위험 보고서 진입 | G41: 지금까지 수행한 분석 기록 목록이 표시된다. | H41: Pass
B42: TC-025 | D42: 기타 | E42: 분석 제목 수정 | F42: 분석 목록 → 옵션 → 제목 수정 → 새 제목 입력 → 저장 | G42: 수정한 제목이 분석 목록에 반영된다. | H42: Pass
B43: TC-027 | C43: AI 상담 | D43: 상담 기능 | E43: 추천 질문 | F43: AI 상담 → 추천 주제 선택 → 추천 질문 클릭 | G43: 새 대화가 생성되고 선택한 질문에 대한 AI 답변이 표시된다. | H43: Pass
...
